INFO [2025-07-25 22:00:48,526] [logger.init:101]: Logger baþlatýldý - Seviye: DEBUG, Dosya: c:\wamp64\www\PofuAi\storage\logs\app_2025-07-25.log
INFO [2025-07-25 22:02:39,267] [logger.init:101]: Logger baþlatýldý - Seviye: DEBUG, Dosya: C:\wamp64\www\PofuAi\storage\logs\app_2025-07-25.log
INFO [2025-07-25 22:02:40,458] [logger.init:101]: Logger baþlatýldý - Seviye: DEBUG, Dosya: C:\wamp64\www\PofuAi\storage\logs\app_2025-07-25.log
ERROR [2025-07-25 22:06:58,140] [error_handler._log_error:193]: Hata: 'User' nesnesi 'avatar_url' özelliðine sahip deðil
Traceback:
Traceback (most recent call last):
  File "C:\Users\ilker\AppData\Local\Programs\Python\Python39\lib\site-packages\flask\app.py", line 867, in full_dispatch_request
    rv = self.dispatch_request()
  File "C:\Users\ilker\AppData\Local\Programs\Python\Python39\lib\site-packages\flask\app.py", line 852, in dispatch_request
    return self.ensure_sync(self.view_functions[rule.endpoint])(**view_args)
  File "C:\wamp64\www\PofuAi\app\Controllers\AuthController.py", line 37, in register
    return self._handle_register()
  File "C:\wamp64\www\PofuAi\app\Controllers\AuthController.py", line 153, in _handle_register
    user = auth_service.register_user(data)
  File "C:\wamp64\www\PofuAi\core\Services\auth_service.py", line 57, in register_user
    'user': user.to_dict(),
  File "C:\wamp64\www\PofuAi\app\Models\User.py", line 126, in to_dict
    data['avatar_url'] = self.avatar_url
  File "C:\wamp64\www\PofuAi\core\Database\base_model.py", line 46, in __getattr__
    raise AttributeError(f"'{self.__class__.__name__}' nesnesi '{name}' özelliðine sahip deðil")
AttributeError: 'User' nesnesi 'avatar_url' özelliðine sahip deðil


ERROR [2025-07-25 22:06:58,141] [error_handler._handle_general_error:273]: Hata: 'User' nesnesi 'avatar_url' özelliðine sahip deðil
ERROR [2025-07-25 22:06:58,142] [error_handler._handle_general_error:274]: Traceback:
Traceback (most recent call last):
  File "C:\Users\ilker\AppData\Local\Programs\Python\Python39\lib\site-packages\flask\app.py", line 867, in full_dispatch_request
    rv = self.dispatch_request()
  File "C:\Users\ilker\AppData\Local\Programs\Python\Python39\lib\site-packages\flask\app.py", line 852, in dispatch_request
    return self.ensure_sync(self.view_functions[rule.endpoint])(**view_args)
  File "C:\wamp64\www\PofuAi\app\Controllers\AuthController.py", line 37, in register
    return self._handle_register()
  File "C:\wamp64\www\PofuAi\app\Controllers\AuthController.py", line 153, in _handle_register
    user = auth_service.register_user(data)
  File "C:\wamp64\www\PofuAi\core\Services\auth_service.py", line 57, in register_user
    'user': user.to_dict(),
  File "C:\wamp64\www\PofuAi\app\Models\User.py", line 126, in to_dict
    data['avatar_url'] = self.avatar_url
  File "C:\wamp64\www\PofuAi\core\Database\base_model.py", line 46, in __getattr__
    raise AttributeError(f"'{self.__class__.__name__}' nesnesi '{name}' özelliðine sahip deðil")
AttributeError: 'User' nesnesi 'avatar_url' özelliðine sahip deðil

INFO [2025-07-25 22:17:54,029] [logger.init:101]: Logger baþlatýldý - Seviye: DEBUG, Dosya: C:\wamp64\www\PofuAi\storage\logs\app_2025-07-25.log
INFO [2025-07-25 22:17:55,081] [logger.init:101]: Logger baþlatýldý - Seviye: DEBUG, Dosya: C:\wamp64\www\PofuAi\storage\logs\app_2025-07-25.log
